[2023-11-26T01:13:22.917+0000] {taskinstance.py:1159} INFO - Dependencies all met for dep_context=non-requeueable deps ti=<TaskInstance: outcomes_dag.load scheduled__2023-11-25T00:00:00+00:00 [queued]>
[2023-11-26T01:13:22.937+0000] {taskinstance.py:1159} INFO - Dependencies all met for dep_context=requeueable deps ti=<TaskInstance: outcomes_dag.load scheduled__2023-11-25T00:00:00+00:00 [queued]>
[2023-11-26T01:13:22.938+0000] {taskinstance.py:1361} INFO - Starting attempt 4 of 4
[2023-11-26T01:13:22.966+0000] {taskinstance.py:1382} INFO - Executing <Task(PythonOperator): load> on 2023-11-25 00:00:00+00:00
[2023-11-26T01:13:22.979+0000] {standard_task_runner.py:57} INFO - Started process 953 to run task
[2023-11-26T01:13:22.985+0000] {standard_task_runner.py:84} INFO - Running: ['***', 'tasks', 'run', 'outcomes_dag', 'load', 'scheduled__2023-11-25T00:00:00+00:00', '--job-id', '44', '--raw', '--subdir', 'DAGS_FOLDER/outcomes_dag.py', '--cfg-path', '/tmp/tmpannaifwj']
[2023-11-26T01:13:22.995+0000] {standard_task_runner.py:85} INFO - Job 44: Subtask load
[2023-11-26T01:13:23.296+0000] {task_command.py:416} INFO - Running <TaskInstance: outcomes_dag.load scheduled__2023-11-25T00:00:00+00:00 [running]> on host decfc1fe5c09
[2023-11-26T01:13:23.699+0000] {taskinstance.py:1662} INFO - Exporting env vars: AIRFLOW_CTX_DAG_OWNER='***' AIRFLOW_CTX_DAG_ID='outcomes_dag' AIRFLOW_CTX_TASK_ID='load' AIRFLOW_CTX_EXECUTION_DATE='2023-11-25T00:00:00+00:00' AIRFLOW_CTX_TRY_NUMBER='4' AIRFLOW_CTX_DAG_RUN_ID='scheduled__2023-11-25T00:00:00+00:00'
[2023-11-26T01:13:25.011+0000] {taskinstance.py:1937} ERROR - Task failed with exception
Traceback (most recent call last):
  File "/home/airflow/.local/lib/python3.8/site-packages/airflow/operators/python.py", line 192, in execute
    return_value = self.execute_callable()
  File "/home/airflow/.local/lib/python3.8/site-packages/airflow/operators/python.py", line 209, in execute_callable
    return self.python_callable(*self.op_args, **self.op_kwargs)
  File "/opt/airflow/dags/etl_scripts/load.py", line 12, in load_dim_dates
    client.get_table(table_id)
  File "/home/airflow/.local/lib/python3.8/site-packages/google/cloud/bigquery/client.py", line 1060, in get_table
    api_response = self._call_api(
  File "/home/airflow/.local/lib/python3.8/site-packages/google/cloud/bigquery/client.py", line 808, in _call_api
    return call()
  File "/home/airflow/.local/lib/python3.8/site-packages/google/api_core/retry.py", line 366, in retry_wrapped_func
    return retry_target(
  File "/home/airflow/.local/lib/python3.8/site-packages/google/api_core/retry.py", line 204, in retry_target
    return target()
  File "/home/airflow/.local/lib/python3.8/site-packages/google/cloud/_http/__init__.py", line 494, in api_request
    raise exceptions.from_http_response(response)
google.api_core.exceptions.Forbidden: 403 GET https://bigquery.googleapis.com/bigquery/v2/projects/oceanic-hangout-406022/datasets/outcomes/tables/dim_dates?prettyPrint=false: Access Denied: Table oceanic-hangout-406022:outcomes.dim_dates: Permission bigquery.tables.get denied on table oceanic-hangout-406022:outcomes.dim_dates (or it may not exist).
[2023-11-26T01:13:25.123+0000] {taskinstance.py:1400} INFO - Marking task as FAILED. dag_id=outcomes_dag, task_id=load, execution_date=20231125T000000, start_date=20231126T011322, end_date=20231126T011325
[2023-11-26T01:13:25.232+0000] {standard_task_runner.py:104} ERROR - Failed to execute job 44 for task load (403 GET https://bigquery.googleapis.com/bigquery/v2/projects/oceanic-hangout-406022/datasets/outcomes/tables/dim_dates?prettyPrint=false: Access Denied: Table oceanic-hangout-406022:outcomes.dim_dates: Permission bigquery.tables.get denied on table oceanic-hangout-406022:outcomes.dim_dates (or it may not exist).; 953)
[2023-11-26T01:13:25.304+0000] {local_task_job_runner.py:228} INFO - Task exited with return code 1
[2023-11-26T01:13:25.361+0000] {taskinstance.py:2778} INFO - 0 downstream tasks scheduled from follow-on schedule check
