[2023-12-17T08:15:37.707+0000] {taskinstance.py:1159} INFO - Dependencies all met for dep_context=non-requeueable deps ti=<TaskInstance: outcomes_dag.transform scheduled__2023-11-03T00:00:00+00:00 [queued]>
[2023-12-17T08:15:37.722+0000] {taskinstance.py:1159} INFO - Dependencies all met for dep_context=requeueable deps ti=<TaskInstance: outcomes_dag.transform scheduled__2023-11-03T00:00:00+00:00 [queued]>
[2023-12-17T08:15:37.722+0000] {taskinstance.py:1361} INFO - Starting attempt 1 of 1
[2023-12-17T08:15:37.745+0000] {taskinstance.py:1382} INFO - Executing <Task(PythonOperator): transform> on 2023-11-03 00:00:00+00:00
[2023-12-17T08:15:37.752+0000] {standard_task_runner.py:57} INFO - Started process 217 to run task
[2023-12-17T08:15:37.757+0000] {standard_task_runner.py:84} INFO - Running: ['***', 'tasks', 'run', 'outcomes_dag', 'transform', 'scheduled__2023-11-03T00:00:00+00:00', '--job-id', '22', '--raw', '--subdir', 'DAGS_FOLDER/outcomes_dag.py', '--cfg-path', '/tmp/tmpd0rahjdf']
[2023-12-17T08:15:37.764+0000] {standard_task_runner.py:85} INFO - Job 22: Subtask transform
[2023-12-17T08:15:37.850+0000] {task_command.py:416} INFO - Running <TaskInstance: outcomes_dag.transform scheduled__2023-11-03T00:00:00+00:00 [running]> on host 0cbaf6db6843
[2023-12-17T08:15:38.025+0000] {taskinstance.py:1662} INFO - Exporting env vars: AIRFLOW_CTX_DAG_OWNER='***' AIRFLOW_CTX_DAG_ID='outcomes_dag' AIRFLOW_CTX_TASK_ID='transform' AIRFLOW_CTX_EXECUTION_DATE='2023-11-03T00:00:00+00:00' AIRFLOW_CTX_TRY_NUMBER='1' AIRFLOW_CTX_DAG_RUN_ID='scheduled__2023-11-03T00:00:00+00:00'
[2023-12-17T08:15:45.965+0000] {taskinstance.py:1937} ERROR - Task failed with exception
Traceback (most recent call last):
  File "/home/airflow/.local/lib/python3.8/site-packages/airflow/operators/python.py", line 192, in execute
    return_value = self.execute_callable()
  File "/home/airflow/.local/lib/python3.8/site-packages/airflow/operators/python.py", line 209, in execute_callable
    return self.python_callable(*self.op_args, **self.op_kwargs)
  File "/opt/airflow/dags/etl_scripts/transform.py", line 41, in transform_data
    fct_outcomes = prep_outcomes_fct(data)
  File "/opt/airflow/dags/etl_scripts/transform.py", line 124, in prep_outcomes_fct
    outcomes_fct = data[["animal_id", 'date_id','time','outcome_type_id','outcome_subtype', 'is_fixed']]
  File "/home/airflow/.local/lib/python3.8/site-packages/pandas/core/frame.py", line 3767, in __getitem__
    indexer = self.columns._get_indexer_strict(key, "columns")[1]
  File "/home/airflow/.local/lib/python3.8/site-packages/pandas/core/indexes/base.py", line 5877, in _get_indexer_strict
    self._raise_if_missing(keyarr, indexer, axis_name)
  File "/home/airflow/.local/lib/python3.8/site-packages/pandas/core/indexes/base.py", line 5941, in _raise_if_missing
    raise KeyError(f"{not_found} not in index")
KeyError: "['outcome_subtype'] not in index"
[2023-12-17T08:15:45.988+0000] {taskinstance.py:1400} INFO - Marking task as FAILED. dag_id=outcomes_dag, task_id=transform, execution_date=20231103T000000, start_date=20231217T081537, end_date=20231217T081545
[2023-12-17T08:15:46.018+0000] {standard_task_runner.py:104} ERROR - Failed to execute job 22 for task transform ("['outcome_subtype'] not in index"; 217)
[2023-12-17T08:15:46.045+0000] {local_task_job_runner.py:228} INFO - Task exited with return code 1
[2023-12-17T08:15:46.080+0000] {taskinstance.py:2778} INFO - 0 downstream tasks scheduled from follow-on schedule check
