[2023-11-21T00:48:00.929+0000] {taskinstance.py:1159} INFO - Dependencies all met for dep_context=non-requeueable deps ti=<TaskInstance: outcomes_dag.load_dates_dim scheduled__2023-11-12T00:00:00+00:00 [queued]>
[2023-11-21T00:48:03.827+0000] {taskinstance.py:1159} INFO - Dependencies all met for dep_context=requeueable deps ti=<TaskInstance: outcomes_dag.load_dates_dim scheduled__2023-11-12T00:00:00+00:00 [queued]>
[2023-11-21T00:48:03.873+0000] {taskinstance.py:1361} INFO - Starting attempt 1 of 1
[2023-11-21T00:48:05.115+0000] {taskinstance.py:1382} INFO - Executing <Task(PythonOperator): load_dates_dim> on 2023-11-12 00:00:00+00:00
[2023-11-21T00:48:05.151+0000] {standard_task_runner.py:57} INFO - Started process 436 to run task
[2023-11-21T00:48:05.203+0000] {standard_task_runner.py:84} INFO - Running: ['***', 'tasks', 'run', 'outcomes_dag', 'load_dates_dim', 'scheduled__2023-11-12T00:00:00+00:00', '--job-id', '12', '--raw', '--subdir', 'DAGS_FOLDER/outcomes_dag.py', '--cfg-path', '/tmp/tmpn3yjejnh']
[2023-11-21T00:48:05.309+0000] {standard_task_runner.py:85} INFO - Job 12: Subtask load_dates_dim
[2023-11-21T00:48:07.720+0000] {task_command.py:416} INFO - Running <TaskInstance: outcomes_dag.load_dates_dim scheduled__2023-11-12T00:00:00+00:00 [running]> on host e947633e76f3
[2023-11-21T00:49:15.816+0000] {taskinstance.py:1662} INFO - Exporting env vars: AIRFLOW_CTX_DAG_OWNER='***' AIRFLOW_CTX_DAG_ID='outcomes_dag' AIRFLOW_CTX_TASK_ID='load_dates_dim' AIRFLOW_CTX_EXECUTION_DATE='2023-11-12T00:00:00+00:00' AIRFLOW_CTX_TRY_NUMBER='1' AIRFLOW_CTX_DAG_RUN_ID='scheduled__2023-11-12T00:00:00+00:00'
[2023-11-21T00:49:16.008+0000] {taskinstance.py:1937} ERROR - Task failed with exception
Traceback (most recent call last):
  File "/home/airflow/.local/lib/python3.8/site-packages/airflow/operators/python.py", line 192, in execute
    return_value = self.execute_callable()
  File "/home/airflow/.local/lib/python3.8/site-packages/airflow/operators/python.py", line 209, in execute_callable
    return self.python_callable(*self.op_args, **self.op_kwargs)
  File "/opt/airflow/dags/etl_scripts/load.py", line 19, in load_data
    pd.read_parquet(table_file).to_sql(table_name, conn, if_exists="append", index=False, method=insert_on_conflict_nothing)
  File "/home/airflow/.local/lib/python3.8/site-packages/pandas/io/parquet.py", line 509, in read_parquet
    return impl.read(
  File "/home/airflow/.local/lib/python3.8/site-packages/pandas/io/parquet.py", line 220, in read
    path_or_handle, handles, kwargs["filesystem"] = _get_path_or_handle(
  File "/home/airflow/.local/lib/python3.8/site-packages/pandas/io/parquet.py", line 110, in _get_path_or_handle
    handles = get_handle(
  File "/home/airflow/.local/lib/python3.8/site-packages/pandas/io/common.py", line 868, in get_handle
    handle = open(handle, ioargs.mode)
FileNotFoundError: [Errno 2] No such file or directory: '/opt/airflow/data/2023-11-12/transformed/dim_dates.parquet'
[2023-11-21T00:49:16.052+0000] {taskinstance.py:1400} INFO - Marking task as FAILED. dag_id=outcomes_dag, task_id=load_dates_dim, execution_date=20231112T000000, start_date=20231121T004801, end_date=20231121T004916
[2023-11-21T00:49:16.143+0000] {standard_task_runner.py:104} ERROR - Failed to execute job 12 for task load_dates_dim ([Errno 2] No such file or directory: '/opt/airflow/data/2023-11-12/transformed/dim_dates.parquet'; 436)
[2023-11-21T00:49:16.405+0000] {local_task_job_runner.py:228} INFO - Task exited with return code 1
[2023-11-21T00:49:16.637+0000] {taskinstance.py:2778} INFO - 0 downstream tasks scheduled from follow-on schedule check
