[2023-12-19T06:24:25.732+0000] {taskinstance.py:1159} INFO - Dependencies all met for dep_context=non-requeueable deps ti=<TaskInstance: outcomes_dag.create_cluster manual__2023-12-19T06:24:13.158383+00:00 [queued]>
[2023-12-19T06:24:25.745+0000] {taskinstance.py:1159} INFO - Dependencies all met for dep_context=requeueable deps ti=<TaskInstance: outcomes_dag.create_cluster manual__2023-12-19T06:24:13.158383+00:00 [queued]>
[2023-12-19T06:24:25.746+0000] {taskinstance.py:1361} INFO - Starting attempt 1 of 1
[2023-12-19T06:24:25.760+0000] {taskinstance.py:1382} INFO - Executing <Task(DataprocCreateClusterOperator): create_cluster> on 2023-12-19 06:24:13.158383+00:00
[2023-12-19T06:24:25.768+0000] {standard_task_runner.py:57} INFO - Started process 83 to run task
[2023-12-19T06:24:25.773+0000] {standard_task_runner.py:84} INFO - Running: ['***', 'tasks', 'run', 'outcomes_dag', 'create_cluster', 'manual__2023-12-19T06:24:13.158383+00:00', '--job-id', '4', '--raw', '--subdir', 'DAGS_FOLDER/outcomes_dag.py', '--cfg-path', '/tmp/tmp_wma1gj1']
[2023-12-19T06:24:25.779+0000] {standard_task_runner.py:85} INFO - Job 4: Subtask create_cluster
[2023-12-19T06:24:25.839+0000] {task_command.py:416} INFO - Running <TaskInstance: outcomes_dag.create_cluster manual__2023-12-19T06:24:13.158383+00:00 [running]> on host 50409cb136fe
[2023-12-19T06:24:25.935+0000] {taskinstance.py:1662} INFO - Exporting env vars: AIRFLOW_CTX_DAG_OWNER='***' AIRFLOW_CTX_DAG_ID='outcomes_dag' AIRFLOW_CTX_TASK_ID='create_cluster' AIRFLOW_CTX_EXECUTION_DATE='2023-12-19T06:24:13.158383+00:00' AIRFLOW_CTX_TRY_NUMBER='1' AIRFLOW_CTX_DAG_RUN_ID='manual__2023-12-19T06:24:13.158383+00:00'
[2023-12-19T06:24:25.937+0000] {dataproc.py:637} INFO - Creating cluster: shelter-cluster
[2023-12-19T06:24:25.959+0000] {taskinstance.py:1937} ERROR - Task failed with exception
Traceback (most recent call last):
  File "/home/airflow/.local/lib/python3.8/site-packages/airflow/providers/google/cloud/operators/dataproc.py", line 638, in execute
    hook = DataprocHook(gcp_conn_id=self.gcp_conn_id, impersonation_chain=self.impersonation_chain)
  File "/home/airflow/.local/lib/python3.8/site-packages/airflow/providers/google/cloud/hooks/dataproc.py", line 209, in __init__
    super().__init__(gcp_conn_id=gcp_conn_id, impersonation_chain=impersonation_chain)
  File "/home/airflow/.local/lib/python3.8/site-packages/airflow/providers/google/common/hooks/base_google.py", line 242, in __init__
    self.extras: dict = self.get_connection(self.gcp_conn_id).extra_dejson
  File "/home/airflow/.local/lib/python3.8/site-packages/airflow/hooks/base.py", line 72, in get_connection
    conn = Connection.get_connection_from_secrets(conn_id)
  File "/home/airflow/.local/lib/python3.8/site-packages/airflow/models/connection.py", line 477, in get_connection_from_secrets
    raise AirflowNotFoundException(f"The conn_id `{conn_id}` isn't defined")
airflow.exceptions.AirflowNotFoundException: The conn_id `google_cloud_default` isn't defined
[2023-12-19T06:24:25.965+0000] {taskinstance.py:1400} INFO - Marking task as FAILED. dag_id=outcomes_dag, task_id=create_cluster, execution_date=20231219T062413, start_date=20231219T062425, end_date=20231219T062425
[2023-12-19T06:24:25.983+0000] {standard_task_runner.py:104} ERROR - Failed to execute job 4 for task create_cluster (The conn_id `google_cloud_default` isn't defined; 83)
[2023-12-19T06:24:26.027+0000] {local_task_job_runner.py:228} INFO - Task exited with return code 1
[2023-12-19T06:24:26.057+0000] {taskinstance.py:2778} INFO - 0 downstream tasks scheduled from follow-on schedule check
