[2023-11-26T01:29:48.913+0000] {taskinstance.py:1159} INFO - Dependencies all met for dep_context=non-requeueable deps ti=<TaskInstance: outcomes_dag.load manual__2023-11-26T00:21:04.909924+00:00 [queued]>
[2023-11-26T01:29:48.923+0000] {taskinstance.py:1159} INFO - Dependencies all met for dep_context=requeueable deps ti=<TaskInstance: outcomes_dag.load manual__2023-11-26T00:21:04.909924+00:00 [queued]>
[2023-11-26T01:29:48.924+0000] {taskinstance.py:1361} INFO - Starting attempt 8 of 8
[2023-11-26T01:29:48.938+0000] {taskinstance.py:1382} INFO - Executing <Task(PythonOperator): load> on 2023-11-26 00:21:04.909924+00:00
[2023-11-26T01:29:48.944+0000] {standard_task_runner.py:57} INFO - Started process 1232 to run task
[2023-11-26T01:29:48.947+0000] {standard_task_runner.py:84} INFO - Running: ['***', 'tasks', 'run', 'outcomes_dag', 'load', 'manual__2023-11-26T00:21:04.909924+00:00', '--job-id', '58', '--raw', '--subdir', 'DAGS_FOLDER/outcomes_dag.py', '--cfg-path', '/tmp/tmpor2zh749']
[2023-11-26T01:29:48.951+0000] {standard_task_runner.py:85} INFO - Job 58: Subtask load
[2023-11-26T01:29:49.000+0000] {task_command.py:416} INFO - Running <TaskInstance: outcomes_dag.load manual__2023-11-26T00:21:04.909924+00:00 [running]> on host decfc1fe5c09
[2023-11-26T01:29:49.095+0000] {taskinstance.py:1662} INFO - Exporting env vars: AIRFLOW_CTX_DAG_OWNER='***' AIRFLOW_CTX_DAG_ID='outcomes_dag' AIRFLOW_CTX_TASK_ID='load' AIRFLOW_CTX_EXECUTION_DATE='2023-11-26T00:21:04.909924+00:00' AIRFLOW_CTX_TRY_NUMBER='8' AIRFLOW_CTX_DAG_RUN_ID='manual__2023-11-26T00:21:04.909924+00:00'
[2023-11-26T01:29:50.375+0000] {taskinstance.py:1937} ERROR - Task failed with exception
Traceback (most recent call last):
  File "/opt/airflow/dags/etl_scripts/load.py", line 24, in load_dim_dates
    load_job.result()
  File "/home/airflow/.local/lib/python3.8/site-packages/google/cloud/bigquery/job/base.py", line 922, in result
    return super(_AsyncJob, self).result(timeout=timeout, **kwargs)
  File "/home/airflow/.local/lib/python3.8/site-packages/google/api_core/future/polling.py", line 261, in result
    raise self._exception
google.api_core.exceptions.NotFound: 404 Not found: URI gs://outcomes_bucket/transformed/2023-11-26_dim_dates.csv

During handling of the above exception, another exception occurred:

Traceback (most recent call last):
  File "/home/airflow/.local/lib/python3.8/site-packages/airflow/operators/python.py", line 192, in execute
    return_value = self.execute_callable()
  File "/home/airflow/.local/lib/python3.8/site-packages/airflow/operators/python.py", line 209, in execute_callable
    return self.python_callable(*self.op_args, **self.op_kwargs)
  File "/opt/airflow/dags/etl_scripts/load.py", line 35, in load_dim_dates
    load_job.result()
  File "/home/airflow/.local/lib/python3.8/site-packages/google/cloud/bigquery/job/base.py", line 922, in result
    return super(_AsyncJob, self).result(timeout=timeout, **kwargs)
  File "/home/airflow/.local/lib/python3.8/site-packages/google/api_core/future/polling.py", line 261, in result
    raise self._exception
google.api_core.exceptions.NotFound: 404 Not found: URI gs://outcomes_bucket/transformed/2023-11-26_dim_dates.csv
[2023-11-26T01:29:50.389+0000] {taskinstance.py:1400} INFO - Marking task as FAILED. dag_id=outcomes_dag, task_id=load, execution_date=20231126T002104, start_date=20231126T012948, end_date=20231126T012950
[2023-11-26T01:29:50.403+0000] {standard_task_runner.py:104} ERROR - Failed to execute job 58 for task load (404 Not found: URI gs://outcomes_bucket/transformed/2023-11-26_dim_dates.csv; 1232)
[2023-11-26T01:29:50.413+0000] {local_task_job_runner.py:228} INFO - Task exited with return code 1
[2023-11-26T01:29:50.438+0000] {taskinstance.py:2778} INFO - 0 downstream tasks scheduled from follow-on schedule check
