[2023-11-25T20:26:59.613+0000] {taskinstance.py:1159} INFO - Dependencies all met for dep_context=non-requeueable deps ti=<TaskInstance: outcomes_dag.transform manual__2023-11-25T20:26:37.341770+00:00 [queued]>
[2023-11-25T20:26:59.820+0000] {taskinstance.py:1159} INFO - Dependencies all met for dep_context=requeueable deps ti=<TaskInstance: outcomes_dag.transform manual__2023-11-25T20:26:37.341770+00:00 [queued]>
[2023-11-25T20:26:59.820+0000] {taskinstance.py:1361} INFO - Starting attempt 1 of 1
[2023-11-25T20:26:59.842+0000] {taskinstance.py:1382} INFO - Executing <Task(PythonOperator): transform> on 2023-11-25 20:26:37.341770+00:00
[2023-11-25T20:26:59.851+0000] {standard_task_runner.py:57} INFO - Started process 82 to run task
[2023-11-25T20:26:59.856+0000] {standard_task_runner.py:84} INFO - Running: ['***', 'tasks', 'run', 'outcomes_dag', 'transform', 'manual__2023-11-25T20:26:37.341770+00:00', '--job-id', '6', '--raw', '--subdir', 'DAGS_FOLDER/outcomes_dag.py', '--cfg-path', '/tmp/tmpy4j6q2xv']
[2023-11-25T20:26:59.861+0000] {standard_task_runner.py:85} INFO - Job 6: Subtask transform
[2023-11-25T20:26:59.953+0000] {task_command.py:416} INFO - Running <TaskInstance: outcomes_dag.transform manual__2023-11-25T20:26:37.341770+00:00 [running]> on host 17ac1e2d02c6
[2023-11-25T20:27:00.070+0000] {taskinstance.py:1662} INFO - Exporting env vars: AIRFLOW_CTX_DAG_OWNER='***' AIRFLOW_CTX_DAG_ID='outcomes_dag' AIRFLOW_CTX_TASK_ID='transform' AIRFLOW_CTX_EXECUTION_DATE='2023-11-25T20:26:37.341770+00:00' AIRFLOW_CTX_TRY_NUMBER='1' AIRFLOW_CTX_DAG_RUN_ID='manual__2023-11-25T20:26:37.341770+00:00'
[2023-11-25T20:27:00.410+0000] {taskinstance.py:1937} ERROR - Task failed with exception
Traceback (most recent call last):
  File "/home/airflow/.local/lib/python3.8/site-packages/pandas/core/indexes/base.py", line 3653, in get_loc
    return self._engine.get_loc(casted_key)
  File "pandas/_libs/index.pyx", line 147, in pandas._libs.index.IndexEngine.get_loc
  File "pandas/_libs/index.pyx", line 176, in pandas._libs.index.IndexEngine.get_loc
  File "pandas/_libs/hashtable_class_helper.pxi", line 7080, in pandas._libs.hashtable.PyObjectHashTable.get_item
  File "pandas/_libs/hashtable_class_helper.pxi", line 7088, in pandas._libs.hashtable.PyObjectHashTable.get_item
KeyError: 'Name'

The above exception was the direct cause of the following exception:

Traceback (most recent call last):
  File "/home/airflow/.local/lib/python3.8/site-packages/airflow/operators/python.py", line 192, in execute
    return_value = self.execute_callable()
  File "/home/airflow/.local/lib/python3.8/site-packages/airflow/operators/python.py", line 209, in execute_callable
    return self.python_callable(*self.op_args, **self.op_kwargs)
  File "/opt/airflow/dags/etl_scripts/transform.py", line 36, in transform_data
    data = prep_data(data)
  File "/opt/airflow/dags/etl_scripts/transform.py", line 51, in prep_data
    data['name'] = data['Name'].str.replace("*","",regex=False)
  File "/home/airflow/.local/lib/python3.8/site-packages/pandas/core/frame.py", line 3761, in __getitem__
    indexer = self.columns.get_loc(key)
  File "/home/airflow/.local/lib/python3.8/site-packages/pandas/core/indexes/base.py", line 3655, in get_loc
    raise KeyError(key) from err
KeyError: 'Name'
[2023-11-25T20:27:00.425+0000] {taskinstance.py:1400} INFO - Marking task as FAILED. dag_id=outcomes_dag, task_id=transform, execution_date=20231125T202637, start_date=20231125T202659, end_date=20231125T202700
[2023-11-25T20:27:00.438+0000] {standard_task_runner.py:104} ERROR - Failed to execute job 6 for task transform ('Name'; 82)
[2023-11-25T20:27:00.476+0000] {local_task_job_runner.py:228} INFO - Task exited with return code 1
[2023-11-25T20:27:00.498+0000] {taskinstance.py:2778} INFO - 0 downstream tasks scheduled from follow-on schedule check
