[2023-11-26T03:06:04.219+0000] {taskinstance.py:1159} INFO - Dependencies all met for dep_context=non-requeueable deps ti=<TaskInstance: outcomes_dag.load_outcome_types_dim scheduled__2023-11-25T00:00:00+00:00 [queued]>
[2023-11-26T03:06:04.237+0000] {taskinstance.py:1159} INFO - Dependencies all met for dep_context=requeueable deps ti=<TaskInstance: outcomes_dag.load_outcome_types_dim scheduled__2023-11-25T00:00:00+00:00 [queued]>
[2023-11-26T03:06:04.239+0000] {taskinstance.py:1361} INFO - Starting attempt 1 of 1
[2023-11-26T03:06:04.272+0000] {taskinstance.py:1382} INFO - Executing <Task(PythonOperator): load_outcome_types_dim> on 2023-11-25 00:00:00+00:00
[2023-11-26T03:06:04.282+0000] {standard_task_runner.py:57} INFO - Started process 897 to run task
[2023-11-26T03:06:04.298+0000] {standard_task_runner.py:84} INFO - Running: ['***', 'tasks', 'run', 'outcomes_dag', 'load_outcome_types_dim', 'scheduled__2023-11-25T00:00:00+00:00', '--job-id', '158', '--raw', '--subdir', 'DAGS_FOLDER/outcomes_dag.py', '--cfg-path', '/tmp/tmpfkz8fn1q']
[2023-11-26T03:06:04.314+0000] {standard_task_runner.py:85} INFO - Job 158: Subtask load_outcome_types_dim
[2023-11-26T03:06:04.553+0000] {task_command.py:416} INFO - Running <TaskInstance: outcomes_dag.load_outcome_types_dim scheduled__2023-11-25T00:00:00+00:00 [running]> on host d8c33f99ee50
[2023-11-26T03:06:04.828+0000] {taskinstance.py:1662} INFO - Exporting env vars: AIRFLOW_CTX_DAG_OWNER='***' AIRFLOW_CTX_DAG_ID='outcomes_dag' AIRFLOW_CTX_TASK_ID='load_outcome_types_dim' AIRFLOW_CTX_EXECUTION_DATE='2023-11-25T00:00:00+00:00' AIRFLOW_CTX_TRY_NUMBER='1' AIRFLOW_CTX_DAG_RUN_ID='scheduled__2023-11-25T00:00:00+00:00'
[2023-11-26T03:06:06.156+0000] {python.py:194} INFO - Done. Returned value was: None
[2023-11-26T03:06:06.500+0000] {taskinstance.py:1400} INFO - Marking task as SUCCESS. dag_id=outcomes_dag, task_id=load_outcome_types_dim, execution_date=20231125T000000, start_date=20231126T030604, end_date=20231126T030606
[2023-11-26T03:06:06.826+0000] {local_task_job_runner.py:228} INFO - Task exited with return code 0
[2023-11-26T03:06:06.924+0000] {taskinstance.py:2778} INFO - 0 downstream tasks scheduled from follow-on schedule check
[2023-12-17T15:20:43.748+0000] {taskinstance.py:1159} INFO - Dependencies all met for dep_context=non-requeueable deps ti=<TaskInstance: outcomes_dag.load_outcome_types_dim scheduled__2023-11-25T00:00:00+00:00 [queued]>
[2023-12-17T15:20:43.761+0000] {taskinstance.py:1159} INFO - Dependencies all met for dep_context=requeueable deps ti=<TaskInstance: outcomes_dag.load_outcome_types_dim scheduled__2023-11-25T00:00:00+00:00 [queued]>
[2023-12-17T15:20:43.762+0000] {taskinstance.py:1361} INFO - Starting attempt 1 of 1
[2023-12-17T15:20:43.794+0000] {taskinstance.py:1382} INFO - Executing <Task(PythonOperator): load_outcome_types_dim> on 2023-11-25 00:00:00+00:00
[2023-12-17T15:20:43.827+0000] {standard_task_runner.py:57} INFO - Started process 752 to run task
[2023-12-17T15:20:43.846+0000] {standard_task_runner.py:84} INFO - Running: ['***', 'tasks', 'run', 'outcomes_dag', 'load_outcome_types_dim', 'scheduled__2023-11-25T00:00:00+00:00', '--job-id', '148', '--raw', '--subdir', 'DAGS_FOLDER/outcomes_dag.py', '--cfg-path', '/tmp/tmps85x21ll']
[2023-12-17T15:20:43.862+0000] {standard_task_runner.py:85} INFO - Job 148: Subtask load_outcome_types_dim
[2023-12-17T15:20:43.995+0000] {task_command.py:416} INFO - Running <TaskInstance: outcomes_dag.load_outcome_types_dim scheduled__2023-11-25T00:00:00+00:00 [running]> on host 7f0547651eb4
[2023-12-17T15:20:44.167+0000] {taskinstance.py:1662} INFO - Exporting env vars: AIRFLOW_CTX_DAG_OWNER='***' AIRFLOW_CTX_DAG_ID='outcomes_dag' AIRFLOW_CTX_TASK_ID='load_outcome_types_dim' AIRFLOW_CTX_EXECUTION_DATE='2023-11-25T00:00:00+00:00' AIRFLOW_CTX_TRY_NUMBER='1' AIRFLOW_CTX_DAG_RUN_ID='scheduled__2023-11-25T00:00:00+00:00'
[2023-12-17T15:35:59.149+0000] {connectionpool.py:824} WARNING - Retrying (Retry(total=2, connect=None, read=None, redirect=None, status=None)) after connection broken by 'NewConnectionError('<urllib3.connection.HTTPSConnection object at 0x7f87eeb7b040>: Failed to establish a new connection: [Errno 111] Connection refused')': /token
[2023-12-17T15:35:59.472+0000] {connectionpool.py:824} WARNING - Retrying (Retry(total=1, connect=None, read=None, redirect=None, status=None)) after connection broken by 'NewConnectionError('<urllib3.connection.HTTPSConnection object at 0x7f87eeb7b1c0>: Failed to establish a new connection: [Errno -2] Name or service not known')': /token
[2023-12-17T15:35:59.971+0000] {connectionpool.py:824} WARNING - Retrying (Retry(total=0, connect=None, read=None, redirect=None, status=None)) after connection broken by 'NewConnectionError('<urllib3.connection.HTTPSConnection object at 0x7f87eeb7b340>: Failed to establish a new connection: [Errno -2] Name or service not known')': /token
[2023-12-17T15:36:00.143+0000] {taskinstance.py:1937} ERROR - Task failed with exception
Traceback (most recent call last):
  File "/home/airflow/.local/lib/python3.8/site-packages/urllib3/connection.py", line 174, in _new_conn
    conn = connection.create_connection(
  File "/home/airflow/.local/lib/python3.8/site-packages/urllib3/util/connection.py", line 72, in create_connection
    for res in socket.getaddrinfo(host, port, family, socket.SOCK_STREAM):
  File "/usr/local/lib/python3.8/socket.py", line 918, in getaddrinfo
    for res in _socket.getaddrinfo(host, port, family, type, proto, flags):
socket.gaierror: [Errno -2] Name or service not known

During handling of the above exception, another exception occurred:

Traceback (most recent call last):
  File "/home/airflow/.local/lib/python3.8/site-packages/urllib3/connectionpool.py", line 715, in urlopen
    httplib_response = self._make_request(
  File "/home/airflow/.local/lib/python3.8/site-packages/urllib3/connectionpool.py", line 404, in _make_request
    self._validate_conn(conn)
  File "/home/airflow/.local/lib/python3.8/site-packages/urllib3/connectionpool.py", line 1058, in _validate_conn
    conn.connect()
  File "/home/airflow/.local/lib/python3.8/site-packages/urllib3/connection.py", line 363, in connect
    self.sock = conn = self._new_conn()
  File "/home/airflow/.local/lib/python3.8/site-packages/urllib3/connection.py", line 186, in _new_conn
    raise NewConnectionError(
urllib3.exceptions.NewConnectionError: <urllib3.connection.HTTPSConnection object at 0x7f87eeb7b4f0>: Failed to establish a new connection: [Errno -2] Name or service not known

During handling of the above exception, another exception occurred:

Traceback (most recent call last):
  File "/home/airflow/.local/lib/python3.8/site-packages/requests/adapters.py", line 486, in send
    resp = conn.urlopen(
  File "/home/airflow/.local/lib/python3.8/site-packages/urllib3/connectionpool.py", line 827, in urlopen
    return self.urlopen(
  File "/home/airflow/.local/lib/python3.8/site-packages/urllib3/connectionpool.py", line 827, in urlopen
    return self.urlopen(
  File "/home/airflow/.local/lib/python3.8/site-packages/urllib3/connectionpool.py", line 827, in urlopen
    return self.urlopen(
  File "/home/airflow/.local/lib/python3.8/site-packages/urllib3/connectionpool.py", line 799, in urlopen
    retries = retries.increment(
  File "/home/airflow/.local/lib/python3.8/site-packages/urllib3/util/retry.py", line 592, in increment
    raise MaxRetryError(_pool, url, error or ResponseError(cause))
urllib3.exceptions.MaxRetryError: HTTPSConnectionPool(host='oauth2.googleapis.com', port=443): Max retries exceeded with url: /token (Caused by NewConnectionError('<urllib3.connection.HTTPSConnection object at 0x7f87eeb7b4f0>: Failed to establish a new connection: [Errno -2] Name or service not known'))

During handling of the above exception, another exception occurred:

Traceback (most recent call last):
  File "/home/airflow/.local/lib/python3.8/site-packages/google/auth/transport/requests.py", line 186, in __call__
    response = self.session.request(
  File "/home/airflow/.local/lib/python3.8/site-packages/requests/sessions.py", line 589, in request
    resp = self.send(prep, **send_kwargs)
  File "/home/airflow/.local/lib/python3.8/site-packages/requests/sessions.py", line 703, in send
    r = adapter.send(request, **kwargs)
  File "/home/airflow/.local/lib/python3.8/site-packages/requests/adapters.py", line 519, in send
    raise ConnectionError(e, request=request)
requests.exceptions.ConnectionError: HTTPSConnectionPool(host='oauth2.googleapis.com', port=443): Max retries exceeded with url: /token (Caused by NewConnectionError('<urllib3.connection.HTTPSConnection object at 0x7f87eeb7b4f0>: Failed to establish a new connection: [Errno -2] Name or service not known'))

The above exception was the direct cause of the following exception:

Traceback (most recent call last):
  File "/home/airflow/.local/lib/python3.8/site-packages/google/api_core/retry.py", line 204, in retry_target
    return target()
  File "/home/airflow/.local/lib/python3.8/site-packages/google/cloud/_http/__init__.py", line 482, in api_request
    response = self._make_request(
  File "/home/airflow/.local/lib/python3.8/site-packages/google/cloud/_http/__init__.py", line 341, in _make_request
    return self._do_request(
  File "/home/airflow/.local/lib/python3.8/site-packages/google/cloud/_http/__init__.py", line 379, in _do_request
    return self.http.request(
  File "/home/airflow/.local/lib/python3.8/site-packages/google/auth/transport/requests.py", line 538, in request
    self.credentials.before_request(auth_request, method, url, request_headers)
  File "/home/airflow/.local/lib/python3.8/site-packages/google/auth/credentials.py", line 175, in before_request
    self.refresh(request)
  File "/home/airflow/.local/lib/python3.8/site-packages/google/oauth2/service_account.py", line 438, in refresh
    access_token, expiry, _ = _client.jwt_grant(
  File "/home/airflow/.local/lib/python3.8/site-packages/google/oauth2/_client.py", line 308, in jwt_grant
    response_data = _token_endpoint_request(
  File "/home/airflow/.local/lib/python3.8/site-packages/google/oauth2/_client.py", line 268, in _token_endpoint_request
    response_status_ok, response_data, retryable_error = _token_endpoint_request_no_throw(
  File "/home/airflow/.local/lib/python3.8/site-packages/google/oauth2/_client.py", line 215, in _token_endpoint_request_no_throw
    request_succeeded, response_data, retryable_error = _perform_request()
  File "/home/airflow/.local/lib/python3.8/site-packages/google/oauth2/_client.py", line 191, in _perform_request
    response = request(
  File "/home/airflow/.local/lib/python3.8/site-packages/google/auth/transport/requests.py", line 192, in __call__
    raise new_exc from caught_exc
google.auth.exceptions.TransportError: HTTPSConnectionPool(host='oauth2.googleapis.com', port=443): Max retries exceeded with url: /token (Caused by NewConnectionError('<urllib3.connection.HTTPSConnection object at 0x7f87eeb7b4f0>: Failed to establish a new connection: [Errno -2] Name or service not known'))

The above exception was the direct cause of the following exception:

Traceback (most recent call last):
  File "/home/airflow/.local/lib/python3.8/site-packages/airflow/operators/python.py", line 192, in execute
    return_value = self.execute_callable()
  File "/home/airflow/.local/lib/python3.8/site-packages/airflow/operators/python.py", line 209, in execute_callable
    return self.python_callable(*self.op_args, **self.op_kwargs)
  File "/opt/airflow/dags/etl_scripts/load.py", line 90, in load_dim_outcome_types
    client.get_table(table_id)
  File "/home/airflow/.local/lib/python3.8/site-packages/google/cloud/bigquery/client.py", line 1060, in get_table
    api_response = self._call_api(
  File "/home/airflow/.local/lib/python3.8/site-packages/google/cloud/bigquery/client.py", line 808, in _call_api
    return call()
  File "/home/airflow/.local/lib/python3.8/site-packages/google/api_core/retry.py", line 366, in retry_wrapped_func
    return retry_target(
  File "/home/airflow/.local/lib/python3.8/site-packages/google/api_core/retry.py", line 220, in retry_target
    raise exceptions.RetryError(
google.api_core.exceptions.RetryError: Deadline of 600.0s exceeded while calling target function, last exception: HTTPSConnectionPool(host='oauth2.googleapis.com', port=443): Max retries exceeded with url: /token (Caused by NewConnectionError('<urllib3.connection.HTTPSConnection object at 0x7f87eeb7b4f0>: Failed to establish a new connection: [Errno -2] Name or service not known'))
[2023-12-17T15:36:01.253+0000] {taskinstance.py:1400} INFO - Marking task as FAILED. dag_id=outcomes_dag, task_id=load_outcome_types_dim, execution_date=20231125T000000, start_date=20231217T152043, end_date=20231217T153601
[2023-12-17T15:36:01.508+0000] {standard_task_runner.py:104} ERROR - Failed to execute job 148 for task load_outcome_types_dim (Deadline of 600.0s exceeded while calling target function, last exception: HTTPSConnectionPool(host='oauth2.googleapis.com', port=443): Max retries exceeded with url: /token (Caused by NewConnectionError('<urllib3.connection.HTTPSConnection object at 0x7f87eeb7b4f0>: Failed to establish a new connection: [Errno -2] Name or service not known')); 752)
[2023-12-17T15:36:01.680+0000] {local_task_job_runner.py:228} INFO - Task exited with return code 1
[2023-12-17T15:36:02.160+0000] {taskinstance.py:2778} INFO - 0 downstream tasks scheduled from follow-on schedule check
