[2023-12-17T16:04:58.248+0000] {taskinstance.py:1159} INFO - Dependencies all met for dep_context=non-requeueable deps ti=<TaskInstance: outcomes_dag.load_outcome_types_dim scheduled__2023-12-13T00:00:00+00:00 [queued]>
[2023-12-17T16:04:58.263+0000] {taskinstance.py:1159} INFO - Dependencies all met for dep_context=requeueable deps ti=<TaskInstance: outcomes_dag.load_outcome_types_dim scheduled__2023-12-13T00:00:00+00:00 [queued]>
[2023-12-17T16:04:58.270+0000] {taskinstance.py:1361} INFO - Starting attempt 1 of 1
[2023-12-17T16:04:58.301+0000] {taskinstance.py:1382} INFO - Executing <Task(PythonOperator): load_outcome_types_dim> on 2023-12-13 00:00:00+00:00
[2023-12-17T16:04:58.314+0000] {standard_task_runner.py:57} INFO - Started process 1286 to run task
[2023-12-17T16:04:58.323+0000] {standard_task_runner.py:84} INFO - Running: ['***', 'tasks', 'run', 'outcomes_dag', 'load_outcome_types_dim', 'scheduled__2023-12-13T00:00:00+00:00', '--job-id', '256', '--raw', '--subdir', 'DAGS_FOLDER/outcomes_dag.py', '--cfg-path', '/tmp/tmpq4mmy4_o']
[2023-12-17T16:04:58.331+0000] {standard_task_runner.py:85} INFO - Job 256: Subtask load_outcome_types_dim
[2023-12-17T16:04:58.434+0000] {task_command.py:416} INFO - Running <TaskInstance: outcomes_dag.load_outcome_types_dim scheduled__2023-12-13T00:00:00+00:00 [running]> on host 7f0547651eb4
[2023-12-17T16:04:58.578+0000] {taskinstance.py:1662} INFO - Exporting env vars: AIRFLOW_CTX_DAG_OWNER='***' AIRFLOW_CTX_DAG_ID='outcomes_dag' AIRFLOW_CTX_TASK_ID='load_outcome_types_dim' AIRFLOW_CTX_EXECUTION_DATE='2023-12-13T00:00:00+00:00' AIRFLOW_CTX_TRY_NUMBER='1' AIRFLOW_CTX_DAG_RUN_ID='scheduled__2023-12-13T00:00:00+00:00'
[2023-12-17T16:15:15.179+0000] {taskinstance.py:1937} ERROR - Task failed with exception
Traceback (most recent call last):
  File "/home/airflow/.local/lib/python3.8/site-packages/urllib3/connectionpool.py", line 715, in urlopen
    httplib_response = self._make_request(
  File "/home/airflow/.local/lib/python3.8/site-packages/urllib3/connectionpool.py", line 467, in _make_request
    six.raise_from(e, None)
  File "<string>", line 3, in raise_from
  File "/home/airflow/.local/lib/python3.8/site-packages/urllib3/connectionpool.py", line 462, in _make_request
    httplib_response = conn.getresponse()
  File "/usr/local/lib/python3.8/http/client.py", line 1348, in getresponse
    response.begin()
  File "/usr/local/lib/python3.8/http/client.py", line 316, in begin
    version, status, reason = self._read_status()
  File "/usr/local/lib/python3.8/http/client.py", line 285, in _read_status
    raise RemoteDisconnected("Remote end closed connection without"
http.client.RemoteDisconnected: Remote end closed connection without response

During handling of the above exception, another exception occurred:

Traceback (most recent call last):
  File "/home/airflow/.local/lib/python3.8/site-packages/requests/adapters.py", line 486, in send
    resp = conn.urlopen(
  File "/home/airflow/.local/lib/python3.8/site-packages/urllib3/connectionpool.py", line 799, in urlopen
    retries = retries.increment(
  File "/home/airflow/.local/lib/python3.8/site-packages/urllib3/util/retry.py", line 550, in increment
    raise six.reraise(type(error), error, _stacktrace)
  File "/home/airflow/.local/lib/python3.8/site-packages/urllib3/packages/six.py", line 769, in reraise
    raise value.with_traceback(tb)
  File "/home/airflow/.local/lib/python3.8/site-packages/urllib3/connectionpool.py", line 715, in urlopen
    httplib_response = self._make_request(
  File "/home/airflow/.local/lib/python3.8/site-packages/urllib3/connectionpool.py", line 467, in _make_request
    six.raise_from(e, None)
  File "<string>", line 3, in raise_from
  File "/home/airflow/.local/lib/python3.8/site-packages/urllib3/connectionpool.py", line 462, in _make_request
    httplib_response = conn.getresponse()
  File "/usr/local/lib/python3.8/http/client.py", line 1348, in getresponse
    response.begin()
  File "/usr/local/lib/python3.8/http/client.py", line 316, in begin
    version, status, reason = self._read_status()
  File "/usr/local/lib/python3.8/http/client.py", line 285, in _read_status
    raise RemoteDisconnected("Remote end closed connection without"
urllib3.exceptions.ProtocolError: ('Connection aborted.', RemoteDisconnected('Remote end closed connection without response'))

During handling of the above exception, another exception occurred:

Traceback (most recent call last):
  File "/home/airflow/.local/lib/python3.8/site-packages/google/api_core/retry.py", line 204, in retry_target
    return target()
  File "/home/airflow/.local/lib/python3.8/site-packages/google/cloud/_http/__init__.py", line 482, in api_request
    response = self._make_request(
  File "/home/airflow/.local/lib/python3.8/site-packages/google/cloud/_http/__init__.py", line 341, in _make_request
    return self._do_request(
  File "/home/airflow/.local/lib/python3.8/site-packages/google/cloud/_http/__init__.py", line 379, in _do_request
    return self.http.request(
  File "/home/airflow/.local/lib/python3.8/site-packages/google/auth/transport/requests.py", line 542, in request
    response = super(AuthorizedSession, self).request(
  File "/home/airflow/.local/lib/python3.8/site-packages/requests/sessions.py", line 589, in request
    resp = self.send(prep, **send_kwargs)
  File "/home/airflow/.local/lib/python3.8/site-packages/requests/sessions.py", line 703, in send
    r = adapter.send(request, **kwargs)
  File "/home/airflow/.local/lib/python3.8/site-packages/requests/adapters.py", line 501, in send
    raise ConnectionError(err, request=request)
requests.exceptions.ConnectionError: ('Connection aborted.', RemoteDisconnected('Remote end closed connection without response'))

The above exception was the direct cause of the following exception:

Traceback (most recent call last):
  File "/home/airflow/.local/lib/python3.8/site-packages/airflow/operators/python.py", line 192, in execute
    return_value = self.execute_callable()
  File "/home/airflow/.local/lib/python3.8/site-packages/airflow/operators/python.py", line 209, in execute_callable
    return self.python_callable(*self.op_args, **self.op_kwargs)
  File "/opt/airflow/dags/etl_scripts/load.py", line 90, in load_dim_outcome_types
    client.get_table(table_id)
  File "/home/airflow/.local/lib/python3.8/site-packages/google/cloud/bigquery/client.py", line 1060, in get_table
    api_response = self._call_api(
  File "/home/airflow/.local/lib/python3.8/site-packages/google/cloud/bigquery/client.py", line 808, in _call_api
    return call()
  File "/home/airflow/.local/lib/python3.8/site-packages/google/api_core/retry.py", line 366, in retry_wrapped_func
    return retry_target(
  File "/home/airflow/.local/lib/python3.8/site-packages/google/api_core/retry.py", line 220, in retry_target
    raise exceptions.RetryError(
google.api_core.exceptions.RetryError: Deadline of 600.0s exceeded while calling target function, last exception: ('Connection aborted.', RemoteDisconnected('Remote end closed connection without response'))
[2023-12-17T16:15:16.599+0000] {taskinstance.py:1400} INFO - Marking task as FAILED. dag_id=outcomes_dag, task_id=load_outcome_types_dim, execution_date=20231213T000000, start_date=20231217T160458, end_date=20231217T161516
[2023-12-17T16:15:18.365+0000] {standard_task_runner.py:104} ERROR - Failed to execute job 256 for task load_outcome_types_dim (Deadline of 600.0s exceeded while calling target function, last exception: ('Connection aborted.', RemoteDisconnected('Remote end closed connection without response')); 1286)
[2023-12-17T16:15:18.511+0000] {local_task_job_runner.py:228} INFO - Task exited with return code 1
[2023-12-17T16:15:18.860+0000] {taskinstance.py:2778} INFO - 0 downstream tasks scheduled from follow-on schedule check
