[2023-11-23T21:57:46.480+0000] {taskinstance.py:1159} INFO - Dependencies all met for dep_context=non-requeueable deps ti=<TaskInstance: outcomes_dag.extract scheduled__2023-11-15T00:00:00+00:00 [queued]>
[2023-11-23T21:57:46.563+0000] {taskinstance.py:1159} INFO - Dependencies all met for dep_context=requeueable deps ti=<TaskInstance: outcomes_dag.extract scheduled__2023-11-15T00:00:00+00:00 [queued]>
[2023-11-23T21:57:46.566+0000] {taskinstance.py:1361} INFO - Starting attempt 1 of 1
[2023-11-23T21:57:46.918+0000] {taskinstance.py:1382} INFO - Executing <Task(PythonOperator): extract> on 2023-11-15 00:00:00+00:00
[2023-11-23T21:57:47.191+0000] {standard_task_runner.py:57} INFO - Started process 125 to run task
[2023-11-23T21:57:47.677+0000] {standard_task_runner.py:84} INFO - Running: ['***', 'tasks', 'run', 'outcomes_dag', 'extract', 'scheduled__2023-11-15T00:00:00+00:00', '--job-id', '8', '--raw', '--subdir', 'DAGS_FOLDER/outcomes_dag.py', '--cfg-path', '/tmp/tmpagpip802']
[2023-11-23T21:57:47.829+0000] {standard_task_runner.py:85} INFO - Job 8: Subtask extract
[2023-11-23T21:57:51.227+0000] {task_command.py:416} INFO - Running <TaskInstance: outcomes_dag.extract scheduled__2023-11-15T00:00:00+00:00 [running]> on host 05b2ff981133
[2023-11-23T21:59:55.071+0000] {taskinstance.py:1662} INFO - Exporting env vars: AIRFLOW_CTX_DAG_OWNER='***' AIRFLOW_CTX_DAG_ID='outcomes_dag' AIRFLOW_CTX_TASK_ID='extract' AIRFLOW_CTX_EXECUTION_DATE='2023-11-15T00:00:00+00:00' AIRFLOW_CTX_TRY_NUMBER='1' AIRFLOW_CTX_DAG_RUN_ID='scheduled__2023-11-15T00:00:00+00:00'
[2023-11-23T22:00:23.036+0000] {taskinstance.py:1937} ERROR - Task failed with exception
Traceback (most recent call last):
  File "/home/airflow/.local/lib/python3.8/site-packages/urllib3/connectionpool.py", line 404, in _make_request
    self._validate_conn(conn)
  File "/home/airflow/.local/lib/python3.8/site-packages/urllib3/connectionpool.py", line 1058, in _validate_conn
    conn.connect()
  File "/home/airflow/.local/lib/python3.8/site-packages/urllib3/connection.py", line 419, in connect
    self.sock = ssl_wrap_socket(
  File "/home/airflow/.local/lib/python3.8/site-packages/urllib3/util/ssl_.py", line 449, in ssl_wrap_socket
    ssl_sock = _ssl_wrap_socket_impl(
  File "/home/airflow/.local/lib/python3.8/site-packages/urllib3/util/ssl_.py", line 493, in _ssl_wrap_socket_impl
    return ssl_context.wrap_socket(sock, server_hostname=server_hostname)
  File "/usr/local/lib/python3.8/ssl.py", line 500, in wrap_socket
    return self.sslsocket_class._create(
  File "/usr/local/lib/python3.8/ssl.py", line 1073, in _create
    self.do_handshake()
  File "/usr/local/lib/python3.8/ssl.py", line 1342, in do_handshake
    self._sslobj.do_handshake()
socket.timeout: _ssl.c:1114: The handshake operation timed out

During handling of the above exception, another exception occurred:

Traceback (most recent call last):
  File "/home/airflow/.local/lib/python3.8/site-packages/requests/adapters.py", line 486, in send
    resp = conn.urlopen(
  File "/home/airflow/.local/lib/python3.8/site-packages/urllib3/connectionpool.py", line 799, in urlopen
    retries = retries.increment(
  File "/home/airflow/.local/lib/python3.8/site-packages/urllib3/util/retry.py", line 550, in increment
    raise six.reraise(type(error), error, _stacktrace)
  File "/home/airflow/.local/lib/python3.8/site-packages/urllib3/packages/six.py", line 770, in reraise
    raise value
  File "/home/airflow/.local/lib/python3.8/site-packages/urllib3/connectionpool.py", line 715, in urlopen
    httplib_response = self._make_request(
  File "/home/airflow/.local/lib/python3.8/site-packages/urllib3/connectionpool.py", line 407, in _make_request
    self._raise_timeout(err=e, url=url, timeout_value=conn.timeout)
  File "/home/airflow/.local/lib/python3.8/site-packages/urllib3/connectionpool.py", line 358, in _raise_timeout
    raise ReadTimeoutError(
urllib3.exceptions.ReadTimeoutError: HTTPSConnectionPool(host='data.austintexas.gov', port=443): Read timed out. (read timeout=10)

During handling of the above exception, another exception occurred:

Traceback (most recent call last):
  File "/home/airflow/.local/lib/python3.8/site-packages/airflow/operators/python.py", line 192, in execute
    return_value = self.execute_callable()
  File "/home/airflow/.local/lib/python3.8/site-packages/airflow/operators/python.py", line 209, in execute_callable
    return self.python_callable(*self.op_args, **self.op_kwargs)
  File "/opt/airflow/dags/etl_scripts/extract.py", line 25, in extract_data
    results = client.get("9t4d-g238", where = f"datetime <= '{date}'", limit = 2000) #CHANGE THIS NUMBER
  File "/home/airflow/.local/lib/python3.8/site-packages/sodapy/socrata.py", line 412, in get
    response = self._perform_request(
  File "/home/airflow/.local/lib/python3.8/site-packages/sodapy/socrata.py", line 551, in _perform_request
    response = getattr(self.session, request_type)(uri, **kwargs)
  File "/home/airflow/.local/lib/python3.8/site-packages/requests/sessions.py", line 602, in get
    return self.request("GET", url, **kwargs)
  File "/home/airflow/.local/lib/python3.8/site-packages/requests/sessions.py", line 589, in request
    resp = self.send(prep, **send_kwargs)
  File "/home/airflow/.local/lib/python3.8/site-packages/requests/sessions.py", line 703, in send
    r = adapter.send(request, **kwargs)
  File "/home/airflow/.local/lib/python3.8/site-packages/requests/adapters.py", line 532, in send
    raise ReadTimeout(e, request=request)
requests.exceptions.ReadTimeout: HTTPSConnectionPool(host='data.austintexas.gov', port=443): Read timed out. (read timeout=10)
[2023-11-23T22:00:59.013+0000] {taskinstance.py:1400} INFO - Marking task as FAILED. dag_id=outcomes_dag, task_id=extract, execution_date=20231115T000000, start_date=20231123T215746, end_date=20231123T220058
[2023-11-23T22:01:03.794+0000] {standard_task_runner.py:104} ERROR - Failed to execute job 8 for task extract (HTTPSConnectionPool(host='data.austintexas.gov', port=443): Read timed out. (read timeout=10); 125)
[2023-11-23T22:01:05.518+0000] {local_task_job_runner.py:228} INFO - Task exited with return code 1
[2023-11-23T22:01:07.507+0000] {taskinstance.py:2778} INFO - 0 downstream tasks scheduled from follow-on schedule check
[2023-12-17T15:08:31.024+0000] {taskinstance.py:1159} INFO - Dependencies all met for dep_context=non-requeueable deps ti=<TaskInstance: outcomes_dag.extract scheduled__2023-11-15T00:00:00+00:00 [queued]>
[2023-12-17T15:08:31.033+0000] {taskinstance.py:1159} INFO - Dependencies all met for dep_context=requeueable deps ti=<TaskInstance: outcomes_dag.extract scheduled__2023-11-15T00:00:00+00:00 [queued]>
[2023-12-17T15:08:31.034+0000] {taskinstance.py:1361} INFO - Starting attempt 1 of 1
[2023-12-17T15:08:31.047+0000] {taskinstance.py:1382} INFO - Executing <Task(PythonOperator): extract> on 2023-11-15 00:00:00+00:00
[2023-12-17T15:08:31.053+0000] {standard_task_runner.py:57} INFO - Started process 467 to run task
[2023-12-17T15:08:31.057+0000] {standard_task_runner.py:84} INFO - Running: ['***', 'tasks', 'run', 'outcomes_dag', 'extract', 'scheduled__2023-11-15T00:00:00+00:00', '--job-id', '90', '--raw', '--subdir', 'DAGS_FOLDER/outcomes_dag.py', '--cfg-path', '/tmp/tmp2opozbpy']
[2023-12-17T15:08:31.061+0000] {standard_task_runner.py:85} INFO - Job 90: Subtask extract
[2023-12-17T15:08:31.132+0000] {task_command.py:416} INFO - Running <TaskInstance: outcomes_dag.extract scheduled__2023-11-15T00:00:00+00:00 [running]> on host 7f0547651eb4
[2023-12-17T15:08:31.317+0000] {taskinstance.py:1662} INFO - Exporting env vars: AIRFLOW_CTX_DAG_OWNER='***' AIRFLOW_CTX_DAG_ID='outcomes_dag' AIRFLOW_CTX_TASK_ID='extract' AIRFLOW_CTX_EXECUTION_DATE='2023-11-15T00:00:00+00:00' AIRFLOW_CTX_TRY_NUMBER='1' AIRFLOW_CTX_DAG_RUN_ID='scheduled__2023-11-15T00:00:00+00:00'
[2023-12-17T15:08:35.015+0000] {python.py:194} INFO - Done. Returned value was: None
[2023-12-17T15:08:35.027+0000] {taskinstance.py:1400} INFO - Marking task as SUCCESS. dag_id=outcomes_dag, task_id=extract, execution_date=20231115T000000, start_date=20231217T150831, end_date=20231217T150835
[2023-12-17T15:08:35.086+0000] {local_task_job_runner.py:228} INFO - Task exited with return code 0
[2023-12-17T15:08:35.147+0000] {taskinstance.py:2778} INFO - 0 downstream tasks scheduled from follow-on schedule check
