[2023-11-26T00:50:57.328+0000] {taskinstance.py:1159} INFO - Dependencies all met for dep_context=non-requeueable deps ti=<TaskInstance: outcomes_dag.load manual__2023-11-26T00:21:04.909924+00:00 [queued]>
[2023-11-26T00:50:57.347+0000] {taskinstance.py:1159} INFO - Dependencies all met for dep_context=requeueable deps ti=<TaskInstance: outcomes_dag.load manual__2023-11-26T00:21:04.909924+00:00 [queued]>
[2023-11-26T00:50:57.348+0000] {taskinstance.py:1361} INFO - Starting attempt 3 of 3
[2023-11-26T00:50:57.367+0000] {taskinstance.py:1382} INFO - Executing <Task(PythonOperator): load> on 2023-11-26 00:21:04.909924+00:00
[2023-11-26T00:50:57.373+0000] {standard_task_runner.py:57} INFO - Started process 615 to run task
[2023-11-26T00:50:57.379+0000] {standard_task_runner.py:84} INFO - Running: ['***', 'tasks', 'run', 'outcomes_dag', 'load', 'manual__2023-11-26T00:21:04.909924+00:00', '--job-id', '41', '--raw', '--subdir', 'DAGS_FOLDER/outcomes_dag.py', '--cfg-path', '/tmp/tmp0lw31qcg']
[2023-11-26T00:50:57.385+0000] {standard_task_runner.py:85} INFO - Job 41: Subtask load
[2023-11-26T00:50:57.494+0000] {task_command.py:416} INFO - Running <TaskInstance: outcomes_dag.load manual__2023-11-26T00:21:04.909924+00:00 [running]> on host decfc1fe5c09
[2023-11-26T00:50:57.781+0000] {taskinstance.py:1662} INFO - Exporting env vars: AIRFLOW_CTX_DAG_OWNER='***' AIRFLOW_CTX_DAG_ID='outcomes_dag' AIRFLOW_CTX_TASK_ID='load' AIRFLOW_CTX_EXECUTION_DATE='2023-11-26T00:21:04.909924+00:00' AIRFLOW_CTX_TRY_NUMBER='3' AIRFLOW_CTX_DAG_RUN_ID='manual__2023-11-26T00:21:04.909924+00:00'
[2023-11-26T00:50:58.426+0000] {taskinstance.py:1937} ERROR - Task failed with exception
Traceback (most recent call last):
  File "/home/airflow/.local/lib/python3.8/site-packages/airflow/operators/python.py", line 192, in execute
    return_value = self.execute_callable()
  File "/home/airflow/.local/lib/python3.8/site-packages/airflow/operators/python.py", line 209, in execute_callable
    return self.python_callable(*self.op_args, **self.op_kwargs)
  File "/opt/airflow/dags/etl_scripts/load.py", line 9, in load_dim_dates
    client.get_table(table_id)
  File "/home/airflow/.local/lib/python3.8/site-packages/google/cloud/bigquery/client.py", line 1060, in get_table
    api_response = self._call_api(
  File "/home/airflow/.local/lib/python3.8/site-packages/google/cloud/bigquery/client.py", line 808, in _call_api
    return call()
  File "/home/airflow/.local/lib/python3.8/site-packages/google/api_core/retry.py", line 366, in retry_wrapped_func
    return retry_target(
  File "/home/airflow/.local/lib/python3.8/site-packages/google/api_core/retry.py", line 204, in retry_target
    return target()
  File "/home/airflow/.local/lib/python3.8/site-packages/google/cloud/_http/__init__.py", line 494, in api_request
    raise exceptions.from_http_response(response)
google.api_core.exceptions.Forbidden: 403 GET https://bigquery.googleapis.com/bigquery/v2/projects/oceanic-hangout-406022/datasets/outcomes/tables/dim_dates?prettyPrint=false: Access Denied: Table oceanic-hangout-406022:outcomes.dim_dates: Permission bigquery.tables.get denied on table oceanic-hangout-406022:outcomes.dim_dates (or it may not exist).
[2023-11-26T00:50:58.440+0000] {taskinstance.py:1400} INFO - Marking task as FAILED. dag_id=outcomes_dag, task_id=load, execution_date=20231126T002104, start_date=20231126T005057, end_date=20231126T005058
[2023-11-26T00:50:58.455+0000] {standard_task_runner.py:104} ERROR - Failed to execute job 41 for task load (403 GET https://bigquery.googleapis.com/bigquery/v2/projects/oceanic-hangout-406022/datasets/outcomes/tables/dim_dates?prettyPrint=false: Access Denied: Table oceanic-hangout-406022:outcomes.dim_dates: Permission bigquery.tables.get denied on table oceanic-hangout-406022:outcomes.dim_dates (or it may not exist).; 615)
[2023-11-26T00:50:58.526+0000] {local_task_job_runner.py:228} INFO - Task exited with return code 1
[2023-11-26T00:50:58.560+0000] {taskinstance.py:2778} INFO - 0 downstream tasks scheduled from follow-on schedule check
