[2023-11-26T01:20:52.306+0000] {taskinstance.py:1159} INFO - Dependencies all met for dep_context=non-requeueable deps ti=<TaskInstance: outcomes_dag.load scheduled__2023-11-25T00:00:00+00:00 [queued]>
[2023-11-26T01:20:52.322+0000] {taskinstance.py:1159} INFO - Dependencies all met for dep_context=requeueable deps ti=<TaskInstance: outcomes_dag.load scheduled__2023-11-25T00:00:00+00:00 [queued]>
[2023-11-26T01:20:52.323+0000] {taskinstance.py:1361} INFO - Starting attempt 5 of 5
[2023-11-26T01:20:52.339+0000] {taskinstance.py:1382} INFO - Executing <Task(PythonOperator): load> on 2023-11-25 00:00:00+00:00
[2023-11-26T01:20:52.345+0000] {standard_task_runner.py:57} INFO - Started process 1066 to run task
[2023-11-26T01:20:52.350+0000] {standard_task_runner.py:84} INFO - Running: ['***', 'tasks', 'run', 'outcomes_dag', 'load', 'scheduled__2023-11-25T00:00:00+00:00', '--job-id', '46', '--raw', '--subdir', 'DAGS_FOLDER/outcomes_dag.py', '--cfg-path', '/tmp/tmpnss0_z6g']
[2023-11-26T01:20:52.354+0000] {standard_task_runner.py:85} INFO - Job 46: Subtask load
[2023-11-26T01:20:52.424+0000] {task_command.py:416} INFO - Running <TaskInstance: outcomes_dag.load scheduled__2023-11-25T00:00:00+00:00 [running]> on host decfc1fe5c09
[2023-11-26T01:20:52.528+0000] {taskinstance.py:1662} INFO - Exporting env vars: AIRFLOW_CTX_DAG_OWNER='***' AIRFLOW_CTX_DAG_ID='outcomes_dag' AIRFLOW_CTX_TASK_ID='load' AIRFLOW_CTX_EXECUTION_DATE='2023-11-25T00:00:00+00:00' AIRFLOW_CTX_TRY_NUMBER='5' AIRFLOW_CTX_DAG_RUN_ID='scheduled__2023-11-25T00:00:00+00:00'
[2023-11-26T01:20:52.531+0000] {taskinstance.py:1937} ERROR - Task failed with exception
Traceback (most recent call last):
  File "/home/airflow/.local/lib/python3.8/site-packages/airflow/operators/python.py", line 192, in execute
    return_value = self.execute_callable()
  File "/home/airflow/.local/lib/python3.8/site-packages/airflow/operators/python.py", line 209, in execute_callable
    return self.python_callable(*self.op_args, **self.op_kwargs)
  File "/opt/airflow/dags/etl_scripts/load.py", line 10, in load_dim_dates
    client = bigquery.Client("oceanic-hangout-406022", credentials=credentials)
  File "/home/airflow/.local/lib/python3.8/site-packages/google/cloud/bigquery/client.py", line 235, in __init__
    super(Client, self).__init__(
  File "/home/airflow/.local/lib/python3.8/site-packages/google/cloud/client/__init__.py", line 321, in __init__
    Client.__init__(
  File "/home/airflow/.local/lib/python3.8/site-packages/google/cloud/client/__init__.py", line 167, in __init__
    raise ValueError(_GOOGLE_AUTH_CREDENTIALS_HELP)
ValueError: This library only supports credentials from google-auth-library-python. See https://google-auth.readthedocs.io/en/latest/ for help on authentication with this library.
[2023-11-26T01:20:52.548+0000] {taskinstance.py:1400} INFO - Marking task as FAILED. dag_id=outcomes_dag, task_id=load, execution_date=20231125T000000, start_date=20231126T012052, end_date=20231126T012052
[2023-11-26T01:20:52.560+0000] {standard_task_runner.py:104} ERROR - Failed to execute job 46 for task load (This library only supports credentials from google-auth-library-python. See https://google-auth.readthedocs.io/en/latest/ for help on authentication with this library.; 1066)
[2023-11-26T01:20:52.605+0000] {local_task_job_runner.py:228} INFO - Task exited with return code 1
[2023-11-26T01:20:52.632+0000] {taskinstance.py:2778} INFO - 0 downstream tasks scheduled from follow-on schedule check
