[2023-11-26T01:29:32.764+0000] {taskinstance.py:1159} INFO - Dependencies all met for dep_context=non-requeueable deps ti=<TaskInstance: outcomes_dag.load scheduled__2023-11-23T00:00:00+00:00 [queued]>
[2023-11-26T01:29:32.775+0000] {taskinstance.py:1159} INFO - Dependencies all met for dep_context=requeueable deps ti=<TaskInstance: outcomes_dag.load scheduled__2023-11-23T00:00:00+00:00 [queued]>
[2023-11-26T01:29:32.776+0000] {taskinstance.py:1361} INFO - Starting attempt 2 of 2
[2023-11-26T01:29:32.789+0000] {taskinstance.py:1382} INFO - Executing <Task(PythonOperator): load> on 2023-11-23 00:00:00+00:00
[2023-11-26T01:29:32.795+0000] {standard_task_runner.py:57} INFO - Started process 1216 to run task
[2023-11-26T01:29:32.799+0000] {standard_task_runner.py:84} INFO - Running: ['***', 'tasks', 'run', 'outcomes_dag', 'load', 'scheduled__2023-11-23T00:00:00+00:00', '--job-id', '55', '--raw', '--subdir', 'DAGS_FOLDER/outcomes_dag.py', '--cfg-path', '/tmp/tmp9vgmmbin']
[2023-11-26T01:29:32.803+0000] {standard_task_runner.py:85} INFO - Job 55: Subtask load
[2023-11-26T01:29:32.853+0000] {task_command.py:416} INFO - Running <TaskInstance: outcomes_dag.load scheduled__2023-11-23T00:00:00+00:00 [running]> on host decfc1fe5c09
[2023-11-26T01:29:32.943+0000] {taskinstance.py:1662} INFO - Exporting env vars: AIRFLOW_CTX_DAG_OWNER='***' AIRFLOW_CTX_DAG_ID='outcomes_dag' AIRFLOW_CTX_TASK_ID='load' AIRFLOW_CTX_EXECUTION_DATE='2023-11-23T00:00:00+00:00' AIRFLOW_CTX_TRY_NUMBER='2' AIRFLOW_CTX_DAG_RUN_ID='scheduled__2023-11-23T00:00:00+00:00'
[2023-11-26T01:29:34.394+0000] {taskinstance.py:1937} ERROR - Task failed with exception
Traceback (most recent call last):
  File "/opt/airflow/dags/etl_scripts/load.py", line 24, in load_dim_dates
    load_job.result()
  File "/home/airflow/.local/lib/python3.8/site-packages/google/cloud/bigquery/job/base.py", line 922, in result
    return super(_AsyncJob, self).result(timeout=timeout, **kwargs)
  File "/home/airflow/.local/lib/python3.8/site-packages/google/api_core/future/polling.py", line 261, in result
    raise self._exception
google.api_core.exceptions.NotFound: 404 Not found: URI gs://outcomes_bucket/transformed/2023-11-23_dim_dates.csv

During handling of the above exception, another exception occurred:

Traceback (most recent call last):
  File "/home/airflow/.local/lib/python3.8/site-packages/airflow/operators/python.py", line 192, in execute
    return_value = self.execute_callable()
  File "/home/airflow/.local/lib/python3.8/site-packages/airflow/operators/python.py", line 209, in execute_callable
    return self.python_callable(*self.op_args, **self.op_kwargs)
  File "/opt/airflow/dags/etl_scripts/load.py", line 35, in load_dim_dates
    load_job.result()
  File "/home/airflow/.local/lib/python3.8/site-packages/google/cloud/bigquery/job/base.py", line 922, in result
    return super(_AsyncJob, self).result(timeout=timeout, **kwargs)
  File "/home/airflow/.local/lib/python3.8/site-packages/google/api_core/future/polling.py", line 261, in result
    raise self._exception
google.api_core.exceptions.NotFound: 404 Not found: URI gs://outcomes_bucket/transformed/2023-11-23_dim_dates.csv
[2023-11-26T01:29:34.408+0000] {taskinstance.py:1400} INFO - Marking task as FAILED. dag_id=outcomes_dag, task_id=load, execution_date=20231123T000000, start_date=20231126T012932, end_date=20231126T012934
[2023-11-26T01:29:34.437+0000] {standard_task_runner.py:104} ERROR - Failed to execute job 55 for task load (404 Not found: URI gs://outcomes_bucket/transformed/2023-11-23_dim_dates.csv; 1216)
[2023-11-26T01:29:34.467+0000] {local_task_job_runner.py:228} INFO - Task exited with return code 1
[2023-11-26T01:29:34.486+0000] {taskinstance.py:2778} INFO - 0 downstream tasks scheduled from follow-on schedule check
