[2023-12-19T04:26:49.729+0000] {taskinstance.py:1159} INFO - Dependencies all met for dep_context=non-requeueable deps ti=<TaskInstance: outcomes_dag.create_cluster scheduled__2023-12-18T00:00:00+00:00 [queued]>
[2023-12-19T04:26:49.738+0000] {taskinstance.py:1159} INFO - Dependencies all met for dep_context=requeueable deps ti=<TaskInstance: outcomes_dag.create_cluster scheduled__2023-12-18T00:00:00+00:00 [queued]>
[2023-12-19T04:26:49.739+0000] {taskinstance.py:1361} INFO - Starting attempt 3 of 3
[2023-12-19T04:26:49.755+0000] {taskinstance.py:1382} INFO - Executing <Task(DataprocCreateClusterOperator): create_cluster> on 2023-12-18 00:00:00+00:00
[2023-12-19T04:26:49.768+0000] {standard_task_runner.py:57} INFO - Started process 266 to run task
[2023-12-19T04:26:49.772+0000] {standard_task_runner.py:84} INFO - Running: ['***', 'tasks', 'run', 'outcomes_dag', 'create_cluster', 'scheduled__2023-12-18T00:00:00+00:00', '--job-id', '7', '--raw', '--subdir', 'DAGS_FOLDER/outcomes_dag.py', '--cfg-path', '/tmp/tmpllf1hvpn']
[2023-12-19T04:26:49.776+0000] {standard_task_runner.py:85} INFO - Job 7: Subtask create_cluster
[2023-12-19T04:26:49.856+0000] {task_command.py:416} INFO - Running <TaskInstance: outcomes_dag.create_cluster scheduled__2023-12-18T00:00:00+00:00 [running]> on host 4ab13aa5d6a6
[2023-12-19T04:26:49.966+0000] {taskinstance.py:1662} INFO - Exporting env vars: AIRFLOW_CTX_DAG_OWNER='***' AIRFLOW_CTX_DAG_ID='outcomes_dag' AIRFLOW_CTX_TASK_ID='create_cluster' AIRFLOW_CTX_EXECUTION_DATE='2023-12-18T00:00:00+00:00' AIRFLOW_CTX_TRY_NUMBER='3' AIRFLOW_CTX_DAG_RUN_ID='scheduled__2023-12-18T00:00:00+00:00'
[2023-12-19T04:26:49.970+0000] {dataproc.py:637} INFO - Creating cluster: shelter-cluster
[2023-12-19T04:26:49.989+0000] {taskinstance.py:1937} ERROR - Task failed with exception
Traceback (most recent call last):
  File "/home/airflow/.local/lib/python3.8/site-packages/airflow/providers/google/cloud/operators/dataproc.py", line 638, in execute
    hook = DataprocHook(gcp_conn_id=self.gcp_conn_id, impersonation_chain=self.impersonation_chain)
  File "/home/airflow/.local/lib/python3.8/site-packages/airflow/providers/google/cloud/hooks/dataproc.py", line 209, in __init__
    super().__init__(gcp_conn_id=gcp_conn_id, impersonation_chain=impersonation_chain)
  File "/home/airflow/.local/lib/python3.8/site-packages/airflow/providers/google/common/hooks/base_google.py", line 242, in __init__
    self.extras: dict = self.get_connection(self.gcp_conn_id).extra_dejson
  File "/home/airflow/.local/lib/python3.8/site-packages/airflow/hooks/base.py", line 72, in get_connection
    conn = Connection.get_connection_from_secrets(conn_id)
  File "/home/airflow/.local/lib/python3.8/site-packages/airflow/models/connection.py", line 477, in get_connection_from_secrets
    raise AirflowNotFoundException(f"The conn_id `{conn_id}` isn't defined")
airflow.exceptions.AirflowNotFoundException: The conn_id `google_cloud_default` isn't defined
[2023-12-19T04:26:49.996+0000] {taskinstance.py:1400} INFO - Marking task as FAILED. dag_id=outcomes_dag, task_id=create_cluster, execution_date=20231218T000000, start_date=20231219T042649, end_date=20231219T042649
[2023-12-19T04:26:50.011+0000] {standard_task_runner.py:104} ERROR - Failed to execute job 7 for task create_cluster (The conn_id `google_cloud_default` isn't defined; 266)
[2023-12-19T04:26:50.027+0000] {local_task_job_runner.py:228} INFO - Task exited with return code 1
[2023-12-19T04:26:50.046+0000] {taskinstance.py:2778} INFO - 0 downstream tasks scheduled from follow-on schedule check
