[2023-11-26T02:21:53.147+0000] {taskinstance.py:1159} INFO - Dependencies all met for dep_context=non-requeueable deps ti=<TaskInstance: outcomes_dag.load_dim_animal manual__2023-11-26T02:21:28.119116+00:00 [queued]>
[2023-11-26T02:21:53.198+0000] {taskinstance.py:1159} INFO - Dependencies all met for dep_context=requeueable deps ti=<TaskInstance: outcomes_dag.load_dim_animal manual__2023-11-26T02:21:28.119116+00:00 [queued]>
[2023-11-26T02:21:53.199+0000] {taskinstance.py:1361} INFO - Starting attempt 1 of 1
[2023-11-26T02:21:53.259+0000] {taskinstance.py:1382} INFO - Executing <Task(PythonOperator): load_dim_animal> on 2023-11-26 02:21:28.119116+00:00
[2023-11-26T02:21:53.276+0000] {standard_task_runner.py:57} INFO - Started process 657 to run task
[2023-11-26T02:21:53.289+0000] {standard_task_runner.py:84} INFO - Running: ['***', 'tasks', 'run', 'outcomes_dag', 'load_dim_animal', 'manual__2023-11-26T02:21:28.119116+00:00', '--job-id', '43', '--raw', '--subdir', 'DAGS_FOLDER/outcomes_dag.py', '--cfg-path', '/tmp/tmp4_v581ng']
[2023-11-26T02:21:53.317+0000] {standard_task_runner.py:85} INFO - Job 43: Subtask load_dim_animal
[2023-11-26T02:21:53.425+0000] {task_command.py:416} INFO - Running <TaskInstance: outcomes_dag.load_dim_animal manual__2023-11-26T02:21:28.119116+00:00 [running]> on host 2011df1a4519
[2023-11-26T02:21:53.702+0000] {taskinstance.py:1662} INFO - Exporting env vars: AIRFLOW_CTX_DAG_OWNER='***' AIRFLOW_CTX_DAG_ID='outcomes_dag' AIRFLOW_CTX_TASK_ID='load_dim_animal' AIRFLOW_CTX_EXECUTION_DATE='2023-11-26T02:21:28.119116+00:00' AIRFLOW_CTX_TRY_NUMBER='1' AIRFLOW_CTX_DAG_RUN_ID='manual__2023-11-26T02:21:28.119116+00:00'
[2023-11-26T02:21:54.879+0000] {taskinstance.py:1937} ERROR - Task failed with exception
Traceback (most recent call last):
  File "/home/airflow/.local/lib/python3.8/site-packages/airflow/operators/python.py", line 192, in execute
    return_value = self.execute_callable()
  File "/home/airflow/.local/lib/python3.8/site-packages/airflow/operators/python.py", line 209, in execute_callable
    return self.python_callable(*self.op_args, **self.op_kwargs)
  File "/opt/airflow/dags/etl_scripts/load.py", line 115, in load_dim_animal
    load_job.result()
  File "/home/airflow/.local/lib/python3.8/site-packages/google/cloud/bigquery/job/base.py", line 922, in result
    return super(_AsyncJob, self).result(timeout=timeout, **kwargs)
  File "/home/airflow/.local/lib/python3.8/site-packages/google/api_core/future/polling.py", line 261, in result
    raise self._exception
google.api_core.exceptions.NotFound: 404 Not found: URI gs://outcomes_bucket/transformed/dim_animal_agg.csv
[2023-11-26T02:21:54.934+0000] {taskinstance.py:1400} INFO - Marking task as FAILED. dag_id=outcomes_dag, task_id=load_dim_animal, execution_date=20231126T022128, start_date=20231126T022153, end_date=20231126T022154
[2023-11-26T02:21:54.989+0000] {standard_task_runner.py:104} ERROR - Failed to execute job 43 for task load_dim_animal (404 Not found: URI gs://outcomes_bucket/transformed/dim_animal_agg.csv; 657)
[2023-11-26T02:21:55.047+0000] {local_task_job_runner.py:228} INFO - Task exited with return code 1
[2023-11-26T02:21:55.087+0000] {taskinstance.py:2778} INFO - 0 downstream tasks scheduled from follow-on schedule check
